<?xml version="1.0" ?>
<!-- =================================================================================== -->
<!-- |    This document was autogenerated by xacro from sagittarius_descriptions.xacro | -->
<!-- |    EDITING THIS FILE BY HAND IS NOT RECOMMENDED                                 | -->
<!-- =================================================================================== -->
<robot name="sgr" xmlns:xacro="http://www.ros.org/wiki/xacro">
  <link name="sgr532/base_link">
    <visual>
      <origin rpy="0 0 0" xyz="0 0 0"/>
      <geometry>
        <mesh filename="package://arm_description/meshes/sagittarius_base_link.STL"/>
      </geometry>
      <material name="">
        <color rgba="1 1 1 1"/>
      </material>
    </visual>
    <collision>
      <origin rpy="0 0 0" xyz="0 0 0"/>
      <geometry>
        <mesh filename="package://arm_description/meshes/sagittarius_base_link.STL"/>
      </geometry>
    </collision>
  </link>
  <link name="sgr532/link1">
    <visual>
      <origin rpy="0 0 0" xyz="0 0 0"/>
      <geometry>
        <mesh filename="package://arm_description/meshes/link1.STL"/>
      </geometry>
      <material name="">
        <color rgba="1 1 1 1"/>
      </material>
    </visual>
    <collision>
      <origin rpy="0 0 0" xyz="0 0 0"/>
      <geometry>
        <mesh filename="package://arm_description/meshes/link1.STL"/>
      </geometry>
    </collision>
  </link>
  <joint name="joint1" type="revolute">
    <origin rpy="0 0 0" xyz="0.045 0 0.07"/>
    <parent link="sgr532/base_link"/>
    <child link="sgr532/link1"/>
    <axis xyz="0 0 -1"/>
    <limit effort="100" lower="-2" upper="2" velocity="3.14"/>
  </joint>
  <!-- <transmission name="trans_joint1">
    <type>transmission_interface/SimpleTransmission</type>
    <joint name="joint1">
      <hardwareInterface>hardware_interface/EffortJointInterface</hardwareInterface>
    </joint>
    <actuator name="joint1_motor">
      <mechanicalReduction>1</mechanicalReduction>
    </actuator>
  </transmission> -->
  <link name="sgr532/link2">
    <visual>
      <origin rpy="0 0 0" xyz="0 0 0"/>
      <geometry>
        <mesh filename="package://arm_description/meshes/link2.STL"/>
      </geometry>
      <material name="">
        <color rgba="1 1 1 1"/>
      </material>
    </visual>
    <collision>
      <origin rpy="0 0 0" xyz="0 0 0"/>
      <geometry>
        <mesh filename="package://arm_description/meshes/link2.STL"/>
      </geometry>
    </collision>
  </link>
  <joint name="joint2" type="revolute">
    <origin rpy="0 0 0" xyz="0 -0.0001 0.055"/>
    <parent link="sgr532/link1"/>
    <child link="sgr532/link2"/>
    <axis xyz="0 -1 0"/>
    <limit effort="100" lower="-1.57" upper="1.4" velocity="3.14"/>
  </joint>
  <!-- <transmission name="trans_joint2">
    <type>transmission_interface/SimpleTransmission</type>
    <joint name="joint2">
      <hardwareInterface>hardware_interface/EffortJointInterface</hardwareInterface>
    </joint>
    <actuator name="joint2_motor">
      <mechanicalReduction>1</mechanicalReduction>
    </actuator>
  </transmission> -->
  <link name="sgr532/link3">
    <visual>
      <origin rpy="0 0 0" xyz="0 0 0"/>
      <geometry>
        <mesh filename="package://arm_description/meshes/link3.STL"/>
      </geometry>
      <material name="">
        <color rgba="1 1 1 1"/>
      </material>
    </visual>
    <collision>
      <origin rpy="0 0 0" xyz="0 0 0"/>
      <geometry>
        <mesh filename="package://arm_description/meshes/link3.STL"/>
      </geometry>
    </collision>
  </link>
  <joint name="joint3" type="revolute">
    <origin rpy="0 0 0" xyz="0.033 -0.0001 0.179"/>
    <parent link="sgr532/link2"/>
    <child link="sgr532/link3"/>
    <axis xyz="0 -1 0"/>
    <limit effort="100" lower="-1.48" upper="1.8" velocity="3.14"/>
  </joint>
  <!-- <transmission name="trans_joint3">
    <type>transmission_interface/SimpleTransmission</type>
    <joint name="joint3">
      <hardwareInterface>hardware_interface/EffortJointInterface</hardwareInterface>
    </joint>
    <actuator name="joint3_motor">
      <mechanicalReduction>1</mechanicalReduction>
    </actuator>
  </transmission> -->
  <link name="sgr532/link4">
    <visual>
      <origin rpy="0 0 0" xyz="0 0 0"/>
      <geometry>
        <mesh filename="package://arm_description/meshes/link4.STL"/>
      </geometry>
      <material name="">
        <color rgba="1 1 1 1"/>
      </material>
    </visual>
    <collision>
      <origin rpy="0 0 0" xyz="0 0 0"/>
      <geometry>
        <mesh filename="package://arm_description/meshes/link4.STL"/>
      </geometry>
    </collision>
  </link>
  <joint name="joint4" type="revolute">
    <origin rpy="0 0 0" xyz="0.0845 0 0"/>
    <parent link="sgr532/link3"/>
    <child link="sgr532/link4"/>
    <axis xyz="-1 0 0"/>
    <limit effort="100" lower="-2.90" upper="2.90" velocity="3.14"/>
  </joint>
  <!-- <transmission name="trans_joint4">
    <type>transmission_interface/SimpleTransmission</type>
    <joint name="joint4">
      <hardwareInterface>hardware_interface/EffortJointInterface</hardwareInterface>
    </joint>
    <actuator name="joint4_motor">
      <mechanicalReduction>1</mechanicalReduction>
    </actuator>
  </transmission> -->
  <link name="sgr532/link5">
    <visual>
      <origin rpy="0 0 0" xyz="0 0 0"/>
      <geometry>
        <mesh filename="package://arm_description/meshes/link5.STL"/>
      </geometry>
      <material name="">
        <color rgba="1 1 1 1"/>
      </material>
    </visual>
    <collision>
      <origin rpy="0 0 0" xyz="0 0 0"/>
      <geometry>
        <mesh filename="package://arm_description/meshes/link5.STL"/>
      </geometry>
    </collision>
  </link>
  <joint name="joint5" type="revolute">
    <origin rpy="0 0 0" xyz="0.08435 0.00065 0"/>
    <parent link="sgr532/link4"/>
    <child link="sgr532/link5"/>
    <axis xyz="0 -1 0"/>
    <limit effort="100" lower="-1.8" upper="1.60" velocity="3.14"/>
  </joint>
  <!-- <transmission name="trans_joint5">
    <type>transmission_interface/SimpleTransmission</type>
    <joint name="joint5">
      <hardwareInterface>hardware_interface/EffortJointInterface</hardwareInterface>
    </joint>
    <actuator name="joint5_motor">
      <mechanicalReduction>1</mechanicalReduction>
    </actuator>
  </transmission> -->
  <link name="sgr532/link6">
    <visual>
      <origin rpy="0 0 0" xyz="0 0 0"/>
      <geometry>
        <mesh filename="package://arm_description/meshes/link6.STL"/>
      </geometry>
      <material name="">
        <color rgba="1 1 1 1"/>
      </material>
    </visual>
    <collision>
      <origin rpy="0 0 0" xyz="0 0 0"/>
      <geometry>
        <mesh filename="package://arm_description/meshes/link6.STL"/>
      </geometry>
    </collision>
  </link>
  <joint name="joint6" type="revolute">
    <origin rpy="0 0 0" xyz="0.061387 0 0"/>
    <parent link="sgr532/link5"/>
    <child link="sgr532/link6"/>
    <axis xyz="-1 0 0"/>
    <limit effort="100" lower="-3.1" upper="3.1" velocity="3.14"/>
  </joint>
  <!-- <transmission name="trans_joint6">
    <type>transmission_interface/SimpleTransmission</type>
    <joint name="joint6">
      <hardwareInterface>hardware_interface/EffortJointInterface</hardwareInterface>
    </joint>
    <actuator name="joint6_motor">
      <mechanicalReduction>1</mechanicalReduction>
    </actuator>
  </transmission> -->
  <!-- <link name="sgr532/ar_tag_link">
  </link>
  <joint name="joint_ar_tag_frame" type="fixed">
    <origin rpy="0 0 0" xyz="-0.018 0 0.036"/>
    <parent link="sgr532/link6"/>
    <child link="sgr532/ar_tag_link"/>
    <axis xyz="0 0 0"/>
    <limit effort="100" lower="0" upper="0" velocity="3.14"/>
  </joint>
  <link name="sgr532/link_grasping_frame">
  </link>
  <joint name="joint_grasping_frame" type="fixed">
    <origin rpy="0 0 0" xyz="0.0557 0 0"/>
    <parent link="sgr532/link6"/>
    <child link="sgr532/link_grasping_frame"/>
    <axis xyz="0 0 0"/>
    <limit effort="100" lower="0" upper="0" velocity="3.1"/>
  </joint> -->
  <link name="sgr532/link_gripper_left">
    <visual>
      <origin rpy="0 0 0" xyz="0 0 0"/>
      <geometry>
        <mesh filename="package://arm_description/meshes/link_gripper_left.STL"/>
      </geometry>
      <material name="">
        <color rgba="1 1 1 1"/>
      </material>
    </visual>
    <collision>
      <origin rpy="0 0 0" xyz="0 0 0"/>
      <geometry>
        <mesh filename="package://arm_description/meshes/link_gripper_left.STL"/>
      </geometry>
    </collision>
  </link>
  <joint name="joint_gripper_left" type="prismatic">
    <origin rpy="0 0 0" xyz="0.0695 0.033 0"/>
    <parent link="sgr532/link6"/>
    <child link="sgr532/link_gripper_left"/>
    <axis xyz="0 1 0"/>
    <limit effort="10" lower="-0.034" upper="0" velocity="1.14"/>
  </joint>
  <!-- <transmission name="trans_joint_gripper_left">
    <type>transmission_interface/SimpleTransmission</type>
    <joint name="joint_gripper_left">
      <hardwareInterface>hardware_interface/EffortJointInterface</hardwareInterface>
    </joint>
    <actuator name="joint_gripper_left_motor">
      <mechanicalReduction>1</mechanicalReduction>
    </actuator>
  </transmission> -->
  <link name="sgr532/link_gripper_right">
    <visual>
      <origin rpy="0 0 0" xyz="0 0 0"/>
      <geometry>
        <mesh filename="package://arm_description/meshes/link_gripper_right.STL"/>
      </geometry>
      <material name="">
        <color rgba="1 1 1 1"/>
      </material>
    </visual>
    <collision>
      <origin rpy="0 0 0" xyz="0 0 0"/>
      <geometry>
        <mesh filename="package://arm_description/meshes/link_gripper_right.STL"/>
      </geometry>
    </collision>
  </link>
  <joint name="joint_gripper_right" type="prismatic">
    <origin rpy="0 0 0" xyz="0.0695 -0.033 0"/>
    <parent link="sgr532/link6"/>
    <child link="sgr532/link_gripper_right"/>
    <axis xyz="0 -1 0"/>
    <limit effort="10" lower="-0.034" upper="0" velocity="1.1"/>
  </joint>
  <!-- <transmission name="trans_joint_gripper_right">
    <type>transmission_interface/SimpleTransmission</type>
    <joint name="joint_gripper_right">
      <hardwareInterface>hardware_interface/EffortJointInterface</hardwareInterface>
    </joint>
    <actuator name="joint_gripper_right_motor">
      <mechanicalReduction>1</mechanicalReduction>
    </actuator>
  </transmission> -->
  <!-- <link name="sgr532/usb_cam_link"/>
  <joint name="joint_usb_cam_frame" type="fixed">
    <origin rpy="-1.57 0 -1.57" xyz="0.05 0 0.05825"/>
    <parent link="sgr532/link6"/>
    <child link="sgr532/usb_cam_link"/>
    <axis xyz="0 0 0"/>
    <limit effort="0" lower="0" upper="0" velocity="0.0"/>
  </joint> -->
  <link name="base_footprint"/>
  <joint name="sagittarius_base_link_joint" type="fixed">
    <origin rpy="0 0 0" xyz="0.044 0 0.138"/>
    <parent link="base_footprint"/>
    <child link="sgr532/base_link"/>
  </joint>
</robot>
